Workbook
Name power_mw: Inputs!$B$4
Name capacity_mwh: Inputs!$B$5
Name hours_per_day: Inputs!$B$6
Name acceptance_rate: Inputs!$B$7
Name damas_afrr_up: Inputs!$B$10
Name damas_afrr_down: Inputs!$B$11
Name stack_capacity: Inputs!$B$14
Name stack_activation: Inputs!$B$15
Name market_share_A: Inputs!$B$18
Name capacity_mult_A: Inputs!$B$19
Name activation_mult_A: Inputs!$B$20
Name market_share_B: Inputs!$B$22
Name capacity_mult_B: Inputs!$B$23
Name activation_mult_B: Inputs!$B$24
Name market_share_C: Inputs!$B$26
Name capacity_mult_C: Inputs!$B$27
Name activation_mult_C: Inputs!$B$28
Name market_share_D: Inputs!$B$30
Name capacity_mult_D: Inputs!$B$31
Name activation_mult_D: Inputs!$B$32

Sheet Summary
A1: aFRR scenarios — Current vs PICASSO vs Mature vs Bear | 2025-05-01 → 2026-05-01 (formula-driven)
A3: Battery configuration (common to all 4 scenarios — see Inputs sheet)
A4: Power (MW) | B4: =power_mw | C4: Battery rated power
A5: Energy capacity (MWh) | B5: =capacity_mwh | C5: Daily throughput cap (1 cycle/day)
A6: Acceptance rate | B6: =acceptance_rate | C6: Balanced strategy
A7: Real DAMAS aFRR+ (€/MW/h) | B7: =damas_afrr_up | C7: Edit on Inputs sheet
A8: Real DAMAS aFRR- (€/MW/h) | B8: =damas_afrr_down | C8: Edit on Inputs sheet
A9: Stacking — capacity | B9: =stack_capacity | C9: Physical constraint
A10: Stacking — activation | B10: =stack_activation | C10: Physical constraint
A12: Scenario definitions + LIVE annual totals (formulas pull from each scenario sheet's TOTAL row)
A13: Scenario | B13: Market share | C13: Capacity × | D13: Activation × | E13: Capacity rev (€) | F13: Activation rev (€) | G13: Total annual (€)
A14: A. Current (10%, pre-PICASSO) | B14: =market_share_A | C14: =capacity_mult_A | D14: =activation_mult_A | E14: ='Scenario_A_Current'!F368 | F14: ='Scenario_A_Current'!M368 | G14: ='Scenario_A_Current'!N368
A15: B. PICASSO go-live (−25%) | B15: =market_share_B | C15: =capacity_mult_B | D15: =activation_mult_B | E15: ='Scenario_B_PICASSO'!F368 | F15: ='Scenario_B_PICASSO'!M368 | G15: ='Scenario_B_PICASSO'!N368
A16: C. Mature market (5% share, −40%) | B16: =market_share_C | C16: =capacity_mult_C | D16: =activation_mult_C | E16: ='Scenario_C_Mature'!F368 | F16: ='Scenario_C_Mature'!M368 | G16: ='Scenario_C_Mature'!N368
A17: D. Bear case (2%, full saturation) | B17: =market_share_D | C17: =capacity_mult_D | D17: =activation_mult_D | E17: ='Scenario_D_Bear'!F368 | F17: ='Scenario_D_Bear'!M368 | G17: ='Scenario_D_Bear'!N368
A19: Scenario descriptions
A20: A. Current (10%, pre-PICASSO) | B20: Today's Romanian aFRR market. PICASSO platform NOT yet connected (Romania waiting on Hungary/MAVIR). Battery operator captures 10% of TSO activations (small new entrant in a sparse BESS market — only ~50 MW deployed Romania-wide). Real DAMAS capacity clearing prices apply. Activation revenue uses real per-slot DAMAS settlement prices.
A21: B. PICASSO go-live (−25%) | B21: PICASSO platform activates Romania (expected 2026-2027 once Hungary/MAVIR connects). Cross-border aFRR-energy bid stack caps Romanian extreme activation prices toward European average; capacity prices compress in parallel. Conservative step-down applied: −25% on BOTH capacity bid AND per-slot activation revenue.
A22: C. Mature market (5% share, −40%) | B22: Romanian BESS pipeline (1+ GW announced) materializes through 2027-2028. Market share compresses from 10% to 5% as new BESS deployments compete for the same activation volumes. aFRR capacity prices compress 40% to ~€5/MW/h (matching Germany's current level). Steady-state realistic case for years Y3-Y8.
A23: D. Bear case (2%, full saturation) | B23: Long-term steady state (2030+). Romanian BESS deploys 2-3 GW matching Germany's current density. Market share collapses to 2% per operator. aFRR capacity prices fall 60%. Activation prices fall 50% as PICASSO + thick bid stack normalize Romanian prices to European average. Bankability stress case used by lenders for late-life (Y8-Y15) cashflow projections.
A25: Notes
A26: • FORMULA-DRIVEN VERSION. Edit any yellow cell on Inputs to recompute every scenario instantly.
A27: • All four scenarios run the SAME 10 MW / 20 MWh battery on the SAME real DAMAS market data (366 days × 96 slots/day) — only the market_share, capacity_mult, and activation_mult parameters differ.
A28: • Capacity revenue per day = power × 24h × bid × acceptance × stack_capacity, where bid = MAX(damas_up, damas_down) × capacity_mult per scenario.
A29: • Activation revenue per day = MIN(market × share × acceptance × stack_activation, power × hours, capacity) × actual_avg_settlement_price × activation_mult.
A30: • PICASSO assumption (-25% step-down): conservative read of ENTSO-E PICASSO go-live data from DE/AT/CZ which saw 20-40% reduction in extreme tail prices. Romania expected to connect 2026-2027.
A31: • Mature market (5% share, -40% capacity): extrapolation from Germany's BESS build-out 2022-2024 and current ~€3-4/MW/h aFRR clearing.
A32: • Bear case (2% share, -60% capacity): long-term steady state matching Germany today after their compression, applied to Romania for Y8-Y15 cashflow stress testing.
A33: • Numbers are SIMULATED on real DAMAS data — NOT bankable. Compliance gates (ANRE / OPCOM / PRE / BRP / BSP / FSE) and tariff exemption math apply downstream in investment_service.analyze().

Sheet Scenario_A_Current
A1: Date | B1: Weekday | C1: Selected | D1: Recommended bid (€/MW/h) | E1: Acceptance rate | F1: Capacity revenue (€) | G1: Slots activated (#/96) | H1: Avg activation price (€/MWh) | I1: Max activation price (€/MWh) | J1: Market activations (MWh) | K1: Captured energy (MWh) | L1: Battery cap binding | M1: Activation revenue (€) | N1: Daily revenue (€)
A2: =DAMAS_Daily!A2 | B2: =DAMAS_Daily!B2 | C2: =IF((power_mw*hours_per_day*damas_afrr_up*capacity_mult_A*stack_capacity*acceptance_rate+(MIN(DAMAS_Daily!C2*market_share_A*acceptance_rate*stack_activation,power_mw*hours_per_day,capacity_mwh))*DAMAS_Daily!E2*activation_mult_A)>=(power_mw*hours_per_day*damas_afrr_down*capacity_mult_A*stack_capacity*acceptance_rate+(MIN(DAMAS_Daily!D2*market_share_A*acceptance_rate*stack_activation,power_mw*hours_per_day,capacity_mwh))*DAMAS_Daily!F2*activation_mult_A),"aFRR+","aFRR-") | D2: =IF(C2="aFRR+",damas_afrr_up*capacity_mult_A,damas_afrr_down*capacity_mult_A) | E2: =acceptance_rate | F2: =IF(C2="aFRR+",power_mw*hours_per_day*damas_afrr_up*capacity_mult_A*stack_capacity*acceptance_rate,power_mw*hours_per_day*damas_afrr_down*capacity_mult_A*stack_capacity*acceptance_rate) | G2: =IF(C2="aFRR+",DAMAS_Daily!I2,DAMAS_Daily!J2) | H2: =IF(C2="aFRR+",DAMAS_Daily!E2,DAMAS_Daily!F2) | I2: =IF(C2="aFRR+",DAMAS_Daily!G2,DAMAS_Daily!H2) | J2: =IF(C2="aFRR+",DAMAS_Daily!C2,DAMAS_Daily!D2) | K2: =IF(C2="aFRR+",MIN(DAMAS_Daily!C2*market_share_A*acceptance_rate*stack_activation,power_mw*hours_per_day,capacity_mwh),MIN(DAMAS_Daily!D2*market_share_A*acceptance_rate*stack_activation,power_mw*hours_per_day,capacity_mwh)) | L2: =IF(K2>=capacity_mwh-0.01,"yes","no") | M2: =IF(C2="aFRR+",(MIN(DAMAS_Daily!C2*market_share_A*acceptance_rate*stack_activation,power_mw*hours_per_day,capacity_mwh))*DAMAS_Daily!E2*activation_mult_A,(MIN(DAMAS_Daily!D2*market_share_A*acceptance_rate*stack_activation,power_mw*hours_per_day,capacity_mwh))*DAMAS_Daily!F2*activation_mult_A) | N2: =F2+M2
A3: =DAMAS_Daily!A3 | B3: =DAMAS_Daily!B3 | C3: =IF((power_mw*hours_per_day*damas_afrr_up*capacity_mult_A*stack_capacity*acceptance_rate+(MIN(DAMAS_Daily!C3*market_share_A*acceptance_rate*stack_activation,power_mw*hours_per_day,capacity_mwh))*DAMAS_Daily!E3*activation_mult_A)>=(power_mw*hours_per_day*damas_afrr_down*capacity_mult_A*stack_capacity*acceptance_rate+(MIN(DAMAS_Daily!D3*market_share_A*acceptance_rate*stack_activation,power_mw*hours_per_day,capacity_mwh))*DAMAS_Daily!F3*activation_mult_A),"aFRR+","aFRR-") | D3: =IF(C3="aFRR+",damas_afrr_up*capacity_mult_A,damas_afrr_down*capacity_mult_A) | E3: =acceptance_rate | F3: =IF(C3="aFRR+",power_mw*hours_per_day*damas_afrr_up*capacity_mult_A*stack_capacity*acceptance_rate,power_mw*hours_per_day*damas_afrr_down*capacity_mult_A*stack_capacity*acceptance_rate) | G3: =IF(C3="aFRR+",DAMAS_Daily!I3,DAMAS_Daily!J3) | H3: =IF(C3="aFRR+",DAMAS_Daily!E3,DAMAS_Daily!F3) | I3: =IF(C3="aFRR+",DAMAS_Daily!G3,DAMAS_Daily!H3) | J3: =IF(C3="aFRR+",DAMAS_Daily!C3,DAMAS_Daily!D3) | K3: =IF(C3="aFRR+",MIN(DAMAS_Daily!C3*market_share_A*acceptance_rate*stack_activation,power_mw*hours_per_day,capacity_mwh),MIN(DAMAS_Daily!D3*market_share_A*acceptance_rate*stack_activation,power_mw*hours_per_day,capacity_mwh)) | L3: =IF(K3>=capacity_mwh-0.01,"yes","no") | M3: =IF(C3="aFRR+",(MIN(DAMAS_Daily!C3*market_share_A*acceptance_rate*stack_activation,power_mw*hours_per_day,capacity_mwh))*DAMAS_Daily!E3*activation_mult_A,(MIN(DAMAS_Daily!D3*market_share_A*acceptance_rate*stack_activation,power_mw*hours_per_day,capacity_mwh))*DAMAS_Daily!F3*activation_mult_A) | N3: =F3+M3
A4: =DAMAS_Daily!A4 | B4: =DAMAS_Daily!B4 | C4: =IF((power_mw*hours_per_day*damas_afrr_up*capacity_mult_A*stack_capacity*acceptance_rate+(MIN(DAMAS_Daily!C4*market_share_A*acceptance_rate*stack_activation,power_mw*hours_per_day,capacity_mwh))*DAMAS_Daily!E4*activation_mult_A)>=(power_mw*hours_per_day*damas_afrr_down*capacity_mult_A*stack_capacity*acceptance_rate+(MIN(DAMAS_Daily!D4*market_share_A*acceptance_rate*stack_activation,power_mw*hours_per_day,capacity_mwh))*DAMAS_Daily!F4*activation_mult_A),"aFRR+","aFRR-") | D4: =IF(C4="aFRR+",damas_afrr_up*capacity_mult_A,damas_afrr_down*capacity_mult_A) | E4: =acceptance_rate | F4: =IF(C4="aFRR+",power_mw*hours_per_day*damas_afrr_up*capacity_mult_A*stack_capacity*acceptance_rate,power_mw*hours_per_day*damas_afrr_down*capacity_mult_A*stack_capacity*acceptance_rate) | G4: =IF(C4="aFRR+",DAMAS_Daily!I4,DAMAS_Daily!J4) | H4: =IF(C4="aFRR+",DAMAS_Daily!E4,DAMAS_Daily!F4) | I4: =IF(C4="aFRR+",DAMAS_Daily!G4,DAMAS_Daily!H4) | J4: =IF(C4="aFRR+",DAMAS_Daily!C4,DAMAS_Daily!D4) | K4: =IF(C4="aFRR+",MIN(DAMAS_Daily!C4*market_share_A*acceptance_rate*stack_activation,power_mw*hours_per_day,capacity_mwh),MIN(DAMAS_Daily!D4*market_share_A*acceptance_rate*stack_activation,power_mw*hours_per_day,capacity_mwh)) | L4: =IF(K4>=capacity_mwh-0.01,"yes","no") | M4: =IF(C4="aFRR+",(MIN(DAMAS_Daily!C4*market_share_A*acceptance_rate*stack_activation,power_mw*hours_per_day,capacity_mwh))*DAMAS_Daily!E4*activation_mult_A,(MIN(DAMAS_Daily!D4*market_share_A*acceptance_rate*stack_activation,power_mw*hours_per_day,capacity_mwh))*DAMAS_Daily!F4*activation_mult_A) | N4: =F4+M4
A5: =DAMAS_Daily!A5 | B5: =DAMAS_Daily!B5 | C5: =IF((power_mw*hours_per_day*damas_afrr_up*capacity_mult_A*stack_capacity*acceptance_rate+(MIN(DAMAS_Daily!C5*market_share_A*acceptance_rate*stack_activation,power_mw*hours_per_day,capacity_mwh))*DAMAS_Daily!E5*activation_mult_A)>=(power_mw*hours_per_day*damas_afrr_down*capacity_mult_A*stack_capacity*acceptance_rate+(MIN(DAMAS_Daily!D5*market_share_A*acceptance_rate*stack_activation,power_mw*hours_per_day,capacity_mwh))*DAMAS_Daily!F5*activation_mult_A),"aFRR+","aFRR-") | D5: =IF(C5="aFRR+",damas_afrr_up*capacity_mult_A,damas_afrr_down*capacity_mult_A) | E5: =acceptance_rate | F5: =IF(C5="aFRR+",power_mw*hours_per_day*damas_afrr_up*capacity_mult_A*stack_capacity*acceptance_rate,power_mw*hours_per_day*damas_afrr_down*capacity_mult_A*stack_capacity*acceptance_rate) | G5: =IF(C5="aFRR+",DAMAS_Daily!I5,DAMAS_Daily!J5) | H5: =IF(C5="aFRR+",DAMAS_Daily!E5,DAMAS_Daily!F5) | I5: =IF(C5="aFRR+",DAMAS_Daily!G5,DAMAS_Daily!H5) | J5: =IF(C5="aFRR+",DAMAS_Daily!C5,DAMAS_Daily!D5) | K5: =IF(C5="aFRR+",MIN(DAMAS_Daily!C5*market_share_A*acceptance_rate*stack_activation,power_mw*hours_per_day,capacity_mwh),MIN(DAMAS_Daily!D5*market_share_A*acceptance_rate*stack_activation,power_mw*hours_per_day,capacity_mwh)) | L5: =IF(K5>=capacity_mwh-0.01,"yes","no") | M5: =IF(C5="aFRR+",(MIN(DAMAS_Daily!C5*market_share_A*acceptance_rate*stack_activation,power_mw*hours_per_day,capacity_mwh))*DAMAS_Daily!E5*activation_mult_A,(MIN(DAMAS_Daily!D5*market_share_A*acceptance_rate*stack_activation,power_mw*hours_per_day,capacity_mwh))*DAMAS_Daily!F5*activation_mult_A) | N5: =F5+M5
A6: =DAMAS_Daily!A6 | B6: =DAMAS_Daily!B6 | C6: =IF((power_mw*hours_per_day*damas_afrr_up*capacity_mult_A*stack_capacity*acceptance_rate+(MIN(DAMAS_Daily!C6*market_share_A*acceptance_rate*stack_activation,power_mw*hours_per_day,capacity_mwh))*DAMAS_Daily!E6*activation_mult_A)>=(power_mw*hours_per_day*damas_afrr_down*capacity_mult_A*stack_capacity*acceptance_rate+(MIN(DAMAS_Daily!D6*market_share_A*acceptance_rate*stack_activation,power_mw*hours_per_day,capacity_mwh))*DAMAS_Daily!F6*activation_mult_A),"aFRR+","aFRR-") | D6: =IF(C6="aFRR+",damas_afrr_up*capacity_mult_A,damas_afrr_down*capacity_mult_A) | E6: =acceptance_rate | F6: =IF(C6="aFRR+",power_mw*hours_per_day*damas_afrr_up*capacity_mult_A*stack_capacity*acceptance_rate,power_mw*hours_per_day*damas_afrr_down*capacity_mult_A*stack_capacity*acceptance_rate) | G6: =IF(C6="aFRR+",DAMAS_Daily!I6,DAMAS_Daily!J6) | H6: =IF(C6="aFRR+",DAMAS_Daily!E6,DAMAS_Daily!F6) | I6: =IF(C6="aFRR+",DAMAS_Daily!G6,DAMAS_Daily!H6) | J6: =IF(C6="aFRR+",DAMAS_Daily!C6,DAMAS_Daily!D6) | K6: =IF(C6="aFRR+",MIN(DAMAS_Daily!C6*market_share_A*acceptance_rate*stack_activation,power_mw*hours_per_day,capacity_mwh),MIN(DAMAS_Daily!D6*market_share_A*acceptance_rate*stack_activation,power_mw*hours_per_day,capacity_mwh)) | L6: =IF(K6>=capacity_mwh-0.01,"yes","no") | M6: =IF(C6="aFRR+",(MIN(DAMAS_Daily!C6*market_share_A*acceptance_rate*stack_activation,power_mw*hours_per_day,capacity_mwh))*DAMAS_Daily!E6*activation_mult_A,(MIN(DAMAS_Daily!D6*market_share_A*acceptance_rate*stack_activation,power_mw*hours_per_day,capacity_mwh))*DAMAS_Daily!F6*activation_mult_A) | N6: =F6+M6
A7: =DAMAS_Daily!A7 | B7: =DAMAS_Daily!B7 | C7: =IF((power_mw*hours_per_day*damas_afrr_up*capacity_mult_A*stack_capacity*acceptance_rate+(MIN(DAMAS_Daily!C7*market_share_A*acceptance_rate*stack_activation,power_mw*hours_per_day,capacity_mwh))*DAMAS_Daily!E7*activation_mult_A)>=(power_mw*hours_per_day*damas_afrr_down*capacity_mult_A*stack_capacity*acceptance_rate+(MIN(DAMAS_Daily!D7*market_share_A*acceptance_rate*stack_activation,power_mw*hours_per_day,capacity_mwh))*DAMAS_Daily!F7*activation_mult_A),"aFRR+","aFRR-") | D7: =IF(C7="aFRR+",damas_afrr_up*capacity_mult_A,damas_afrr_down*capacity_mult_A) | E7: =acceptance_rate | F7: =IF(C7="aFRR+",power_mw*hours_per_day*damas_afrr_up*capacity_mult_A*stack_capacity*acceptance_rate,power_mw*hours_per_day*damas_afrr_down*capacity_mult_A*stack_capacity*acceptance_rate) | G7: =IF(C7="aFRR+",DAMAS_Daily!I7,DAMAS_Daily!J7) | H7: =IF(C7="aFRR+",DAMAS_Daily!E7,DAMAS_Daily!F7) | I7: =IF(C7="aFRR+",DAMAS_Daily!G7,DAMAS_Daily!H7) | J7: =IF(C7="aFRR+",DAMAS_Daily!C7,DAMAS_Daily!D7) | K7: =IF(C7="aFRR+",MIN(DAMAS_Daily!C7*market_share_A*acceptance_rate*stack_activation,power_mw*hours_per_day,capacity_mwh),MIN(DAMAS_Daily!D7*market_share_A*acceptance_rate*stack_activation,power_mw*hours_per_day,capacity_mwh)) | L7: =IF(K7>=capacity_mwh-0.01,"yes","no") | M7: =IF(C7="aFRR+",(MIN(DAMAS_Daily!C7*market_share_A*acceptance_rate*stack_activation,power_mw*hours_per_day,capacity_mwh))*DAMAS_Daily!E7*activation_mult_A,(MIN(DAMAS_Daily!D7*market_share_A*acceptance_rate*stack_activation,power_mw*hours_per_day,capacity_mwh))*DAMAS_Daily!F7*activation_mult_A) | N7: =F7+M7
A8: =DAMAS_Daily!A8 | B8: =DAMAS_Daily!B8 | C8: =IF((power_mw*hours_per_day*damas_afrr_up*capacity_mult_A*stack_capacity*acceptance_rate+(MIN(DAMAS_Daily!C8*market_share_A*acceptance_rate*stack_activation,power_mw*hours_per_day,capacity_mwh))*DAMAS_Daily!E8*activation_mult_A)>=(power_mw*hours_per_day*damas_afrr_down*capacity_mult_A*stack_capacity*acceptance_rate+(MIN(DAMAS_Daily!D8*market_share_A*acceptance_rate*stack_activation,power_mw*hours_per_day,capacity_mwh))*DAMAS_Daily!F8*activation_mult_A),"aFRR+","aFRR-") | D8: =IF(C8="aFRR+",damas_afrr_up*capacity_mult_A,damas_afrr_down*capacity_mult_A) | E8: =acceptance_rate | F8: =IF(C8="aFRR+",power_mw*hours_per_day*damas_afrr_up*capacity_mult_A*stack_capacity*acceptance_rate,power_mw*hours_per_day*damas_afrr_down*capacity_mult_A*stack_capacity*acceptance_rate) | G8: =IF(C8="aFRR+",DAMAS_Daily!I8,DAMAS_Daily!J8) | H8: =IF(C8="aFRR+",DAMAS_Daily!E8,DAMAS_Daily!F8) | I8: =IF(C8="aFRR+",DAMAS_Daily!G8,DAMAS_Daily!H8) | J8: =IF(C8="aFRR+",DAMAS_Daily!C8,DAMAS_Daily!D8) | K8: =IF(C8="aFRR+",MIN(DAMAS_Daily!C8*market_share_A*acceptance_rate*stack_activation,power_mw*hours_per_day,capacity_mwh),MIN(DAMAS_Daily!D8*market_share_A*acceptance_rate*stack_activation,power_mw*hours_per_day,capacity_mwh)) | L8: =IF(K8>=capacity_mwh-0.01,"yes","no") | M8: =IF(C8="aFRR+",(MIN(DAMAS_Daily!C8*market_share_A*acceptance_rate*stack_activation,power_mw*hours_per_day,capacity_mwh))*DAMAS_Daily!E8*activation_mult_A,(MIN(DAMAS_Daily!D8*market_share_A*acceptance_rate*stack_activation,power_mw*hours_per_day,capacity_mwh))*DAMAS_Daily!F8*activation_mult_A) | N8: =F8+M8
A9: =DAMAS_Daily!A9 | B9: =DAMAS_Daily!B9 | C9: =IF((power_mw*hours_per_day*damas_afrr_up*capacity_mult_A*stack_capacity*acceptance_rate+(MIN(DAMAS_Daily!C9*market_share_A*acceptance_rate*stack_activation,power_mw*hours_per_day,capacity_mwh))*DAMAS_Daily!E9*activation_mult_A)>=(power_mw*hours_per_day*damas_afrr_down*capacity_mult_A*stack_capacity*acceptance_rate+(MIN(DAMAS_Daily!D9*market_share_A*acceptance_rate*stack_activation,power_mw*hours_per_day,capacity_mwh))*DAMAS_Daily!F9*activation_mult_A),"aFRR+","aFRR-") | D9: =IF(C9="aFRR+",damas_afrr_up*capacity_mult_A,damas_afrr_down*capacity_mult_A) | E9: =acceptance_rate | F9: =IF(C9="aFRR+",power_mw*hours_per_day*damas_afrr_up*capacity_mult_A*stack_capacity*acceptance_rate,power_mw*hours_per_day*damas_afrr_down*capacity_mult_A*stack_capacity*acceptance_rate) | G9: =IF(C9="aFRR+",DAMAS_Daily!I9,DAMAS_Daily!J9) | H9: =IF(C9="aFRR+",DAMAS_Daily!E9,DAMAS_Daily!F9) | I9: =IF(C9="aFRR+",DAMAS_Daily!G9,DAMAS_Daily!H9) | J9: =IF(C9="aFRR+",DAMAS_Daily!C9,DAMAS_Daily!D9) | K9: =IF(C9="aFRR+",MIN(DAMAS_Daily!C9*market_share_A*acceptance_rate*stack_activation,power_mw*hours_per_day,capacity_mwh),MIN(DAMAS_Daily!D9*market_share_A*acceptance_rate*stack_activation,power_mw*hours_per_day,capacity_mwh)) | L9: =IF(K9>=capacity_mwh-0.01,"yes","no") | M9: =IF(C9="aFRR+",(MIN(DAMAS_Daily!C9*market_share_A*acceptance_rate*stack_activation,power_mw*hours_per_day,capacity_mwh))*DAMAS_Daily!E9*activation_mult_A,(MIN(DAMAS_Daily!D9*market_share_A*acceptance_rate*stack_activation,power_mw*hours_per_day,capacity_mwh))*DAMAS_Daily!F9*activation_mult_A) | N9: =F9+M9
A10: =DAMAS_Daily!A10 | B10: =DAMAS_Daily!B10 | C10: =IF((power_mw*hours_per_day*damas_afrr_up*capacity_mult_A*stack_capacity*acceptance_rate+(MIN(DAMAS_Daily!C10*market_share_A*acceptance_rate*stack_activation,power_mw*hours_per_day,capacity_mwh))*DAMAS_Daily!E10*activation_mult_A)>=(power_mw*hours_per_day*damas_afrr_down*capacity_mult_A*stack_capacity*acceptance_rate+(MIN(DAMAS_Daily!D10*market_share_A*acceptance_rate*stack_activation,power_mw*hours_per_day,capacity_mwh))*DAMAS_Daily!F10*activation_mult_A),"aFRR+","aFRR-") | D10: =IF(C10="aFRR+",damas_afrr_up*capacity_mult_A,damas_afrr_down*capacity_mult_A) | E10: =acceptance_rate | F10: =IF(C10="aFRR+",power_mw*hours_per_day*damas_afrr_up*capacity_mult_A*stack_capacity*acceptance_rate,power_mw*hours_per_day*damas_afrr_down*capacity_mult_A*stack_capacity*acceptance_rate) | G10: =IF(C10="aFRR+",DAMAS_Daily!I10,DAMAS_Daily!J10) | H10: =IF(C10="aFRR+",DAMAS_Daily!E10,DAMAS_Daily!F10) | I10: =IF(C10="aFRR+",DAMAS_Daily!G10,DAMAS_Daily!H10) | J10: =IF(C10="aFRR+",DAMAS_Daily!C10,DAMAS_Daily!D10) | K10: =IF(C10="aFRR+",MIN(DAMAS_Daily!C10*market_share_A*acceptance_rate*stack_activation,power_mw*hours_per_day,capacity_mwh),MIN(DAMAS_Daily!D10*market_share_A*acceptance_rate*stack_activation,power_mw*hours_per_day,capacity_mwh)) | L10: =IF(K10>=capacity_mwh-0.01,"yes","no") | M10: =IF(C10="aFRR+",(MIN(DAMAS_Daily!C10*market_share_A*acceptance_rate*stack_activation,power_mw*hours_per_day,capacity_mwh))*DAMAS_Daily!E10*activation_mult_A,(MIN(DAMAS_Daily!D10*market_share_A*acceptance_rate*stack_activation,power_mw*hours_per_day,capacity_mwh))*DAMAS_Daily!F10*activation_mult_A) | N10: =F10+M10
A11: =DAMAS_Daily!A11 | B11: =DAMAS_Daily!B11 | C11: =IF((power_mw*hours_per_day*damas_afrr_up*capacity_mult_A*stack_capacity*acceptance_rate+(MIN(DAMAS_Daily!C11*market_share_A*acceptance_rate*stack_activation,power_mw*hours_per_day,capacity_mwh))*DAMAS_Daily!E11*activation_mult_A)>=(power_mw*hours_per_day*damas_afrr_down*capacity_mult_A*stack_capacity*acceptance_rate+(MIN(DAMAS_Daily!D11*market_share_A*acceptance_rate*stack_activation,power_mw*hours_per_day,capacity_mwh))*DAMAS_Daily!F11*activation_mult_A),"aFRR+","aFRR-") | D11: =IF(C11="aFRR+",damas_afrr_up*capacity_mult_A,damas_afrr_down*capacity_mult_A) | E11: =acceptance_rate | F11: =IF(C11="aFRR+",power_mw*hours_per_day*damas_afrr_up*capacity_mult_A*stack_capacity*acceptance_rate,power_mw*hours_per_day*damas_afrr_down*capacity_mult_A*stack_capacity*acceptance_rate) | G11: =IF(C11="aFRR+",DAMAS_Daily!I11,DAMAS_Daily!J11) | H11: =IF(C11="aFRR+",DAMAS_Daily!E11,DAMAS_Daily!F11) | I11: =IF(C11="aFRR+",DAMAS_Daily!G11,DAMAS_Daily!H11) | J11: =IF(C11="aFRR+",DAMAS_Daily!C11,DAMAS_Daily!D11) | K11: =IF(C11="aFRR+",MIN(DAMAS_Daily!C11*market_share_A*acceptance_rate*stack_activation,power_mw*hours_per_day,capacity_mwh),MIN(DAMAS_Daily!D11*market_share_A*acceptance_rate*stack_activation,power_mw*hours_per_day,capacity_mwh)) | L11: =IF(K11>=capacity_mwh-0.01,"yes","no") | M11: =IF(C11="aFRR+",(MIN(DAMAS_Daily!C11*market_share_A*acceptance_rate*stack_activation,power_mw*hours_per_day,capacity_mwh))*DAMAS_Daily!E11*activation_mult_A,(MIN(DAMAS_Daily!D11*market_share_A*acceptance_rate*stack_activation,power_mw*hours_per_day,capacity_mwh))*DAMAS_Daily!F11*activation_mult_A) | N11: =F11+M11
A12: =DAMAS_Daily!A12 | B12: =DAMAS_Daily!B12 | C12: =IF((power_mw*hours_per_day*damas_afrr_up*capacity_mult_A*stack_capacity*acceptance_rate+(MIN(DAMAS_Daily!C12*market_share_A*acceptance_rate*stack_activation,power_mw*hours_per_day,capacity_mwh))*DAMAS_Daily!E12*activation_mult_A)>=(power_mw*hours_per_day*damas_afrr_down*capacity_mult_A*stack_capacity*acceptance_rate+(MIN(DAMAS_Daily!D12*market_share_A*acceptance_rate*stack_activation,power_mw*hours_per_day,capacity_mwh))*DAMAS_Daily!F12*activation_mult_A),"aFRR+","aFRR-") | D12: =IF(C12="aFRR+",damas_afrr_up*capacity_mult_A,damas_afrr_down*capacity_mult_A) | E12: =acceptance_rate | F12: =IF(C12="aFRR+",power_mw*hours_per_day*damas_afrr_up*capacity_mult_A*stack_capacity*acceptance_rate,power_mw*hours_per_day*damas_afrr_down*capacity_mult_A*stack_capacity*acceptance_rate) | G12: =IF(C12="aFRR+",DAMAS_Daily!I12,DAMAS_Daily!J12) | H12: =IF(C12="aFRR+",DAMAS_Daily!E12,DAMAS_Daily!F12) | I12: =IF(C12="aFRR+",DAMAS_Daily!G12,DAMAS_Daily!H12) | J12: =IF(C12="aFRR+",DAMAS_Daily!C12,DAMAS_Daily!D12) | K12: =IF(C12="aFRR+",MIN(DAMAS_Daily!C12*market_share_A*acceptance_rate*stack_activation,power_mw*hours_per_day,capacity_mwh),MIN(DAMAS_Daily!D12*market_share_A*acceptance_rate*stack_activation,power_mw*hours_per_day,capacity_mwh)) | L12: =IF(K12>=capacity_mwh-0.01,"yes","no") | M12: =IF(C12="aFRR+",(MIN(DAMAS_Daily!C12*market_share_A*acceptance_rate*stack_activation,power_mw*hours_per_day,capacity_mwh))*DAMAS_Daily!E12*activation_mult_A,(MIN(DAMAS_Daily!D12*market_share_A*acceptance_rate*stack_activation,power_mw*hours_per_day,capacity_mwh))*DAMAS_Daily!F12*activation_mult_A) | N12: =F12+M12
A13: =DAMAS_Daily!A13 | B13: =DAMAS_Daily!B13 | C13: =IF((power_mw*hours_per_day*damas_afrr_up*capacity_mult_A*stack_capacity*acceptance_rate+(MIN(DAMAS_Daily!C13*market_share_A*acceptance_rate*stack_activation,power_mw*hours_per_day,capacity_mwh))*DAMAS_Daily!E13*activation_mult_A)>=(power_mw*hours_per_day*damas_afrr_down*capacity_mult_A*stack_capacity*acceptance_rate+(MIN(DAMAS_Daily!D13*market_share_A*acceptance_rate*stack_activation,power_mw*hours_per_day,capacity_mwh))*DAMAS_Daily!F13*activation_mult_A),"aFRR+","aFRR-") | D13: =IF(C13="aFRR+",damas_afrr_up*capacity_mult_A,damas_afrr_down*capacity_mult_A) | E13: =acceptance_rate | F13: =IF(C13="aFRR+",power_mw*hours_per_day*damas_afrr_up*capacity_mult_A*stack_capacity*acceptance_rate,power_mw*hours_per_day*damas_afrr_down*capacity_mult_A*stack_capacity*acceptance_rate) | G13: =IF(C13="aFRR+",DAMAS_Daily!I13,DAMAS_Daily!J13) | H13: =IF(C13="aFRR+",DAMAS_Daily!E13,DAMAS_Daily!F13) | I13: =IF(C13="aFRR+",DAMAS_Daily!G13,DAMAS_Daily!H13) | J13: =IF(C13="aFRR+",DAMAS_Daily!C13,DAMAS_Daily!D13) | K13: =IF(C13="aFRR+",MIN(DAMAS_Daily!C13*market_share_A*acceptance_rate*stack_activation,power_mw*hours_per_day,capacity_mwh),MIN(DAMAS_Daily!D13*market_share_A*acceptance_rate*stack_activation,power_mw*hours_per_day,capacity_mwh)) | L13: =IF(K13>=capacity_mwh-0.01,"yes","no") | M13: =IF(C13="aFRR+",(MIN(DAMAS_Daily!C13*market_share_A*acceptance_rate*stack_activation,power_mw*hours_per_day,capacity_mwh))*DAMAS_Daily!E13*activation_mult_A,(MIN(DAMAS_Daily!D13*market_share_A*acceptance_rate*stack_activation,power_mw*hours_per_day,capacity_mwh))*DAMAS_Daily!F13*activation_mult_A) | N13: =F13+M13
... A367: =DAMAS_Daily!A367 | B367: =DAMAS_Daily!B367 | C367: =IF((power_mw*hours_per_day*damas_afrr_up*capacity_mult_A*stack_capacity*acceptance_rate+(MIN(DAMAS_Daily!C367*market_share_A*acceptance_rate*stack_activation,power_mw*hours_per_day,capacity_mwh))*DAMAS_Daily!E367*activation_mult_A)>=(power_mw*hours_per_day*damas_afrr_down*capacity_mult_A*stack_capacity*acceptance_rate+(MIN(DAMAS_Daily!D367*market_share_A*acceptance_rate*stack_activation,power_mw*hours_per_day,capacity_mwh))*DAMAS_Daily!F367*activation_mult_A),"aFRR+","aFRR-") | D367: =IF(C367="aFRR+",damas_afrr_up*capacity_mult_A,damas_afrr_down*capacity_mult_A) | E367: =acceptance_rate | F367: =IF(C367="aFRR+",power_mw*hours_per_day*damas_afrr_up*capacity_mult_A*stack_capacity*acceptance_rate,power_mw*hours_per_day*damas_afrr_down*capacity_mult_A*stack_capacity*acceptance_rate) | G367: =IF(C367="aFRR+",DAMAS_Daily!I367,DAMAS_Daily!J367) | H367: =IF(C367="aFRR+",DAMAS_Daily!E367,DAMAS_Daily!F367) | I367: =IF(C367="aFRR+",DAMAS_Daily!G367,DAMAS_Daily!H367) | J367: =IF(C367="aFRR+",DAMAS_Daily!C367,DAMAS_Daily!D367) | K367: =IF(C367="aFRR+",MIN(DAMAS_Daily!C367*market_share_A*acceptance_rate*stack_activation,power_mw*hours_per_day,capacity_mwh),MIN(DAMAS_Daily!D367*market_share_A*acceptance_rate*stack_activation,power_mw*hours_per_day,capacity_mwh)) | L367: =IF(K367>=capacity_mwh-0.01,"yes","no") | M367: =IF(C367="aFRR+",(MIN(DAMAS_Daily!C367*market_share_A*acceptance_rate*stack_activation,power_mw*hours_per_day,capacity_mwh))*DAMAS_Daily!E367*activation_mult_A,(MIN(DAMAS_Daily!D367*market_share_A*acceptance_rate*stack_activation,power_mw*hours_per_day,capacity_mwh))*DAMAS_Daily!F367*activation_mult_A) | N367: =F367+M367
A368: TOTAL | B368: 366 days | C368: — | F368: =SUM(F2:F367) | G368: =SUM(G2:G367) | K368: =SUM(K2:K367) | M368: =SUM(M2:M367) | N368: =SUM(N2:N367)

Sheet Scenario_B_PICASSO
A1: Date | B1: Weekday | C1: Selected | D1: Recommended bid (€/MW/h) | E1: Acceptance rate | F1: Capacity revenue (€) | G1: Slots activated (#/96) | H1: Avg activation price (€/MWh) | I1: Max activation price (€/MWh) | J1: Market activations (MWh) | K1: Captured energy (MWh) | L1: Battery cap binding | M1: Activation revenue (€) | N1: Daily revenue (€)
A2: =DAMAS_Daily!A2 | B2: =DAMAS_Daily!B2 | C2: =IF((power_mw*hours_per_day*damas_afrr_up*capacity_mult_B*stack_capacity*acceptance_rate+(MIN(DAMAS_Daily!C2*market_share_B*acceptance_rate*stack_activation,power_mw*hours_per_day,capacity_mwh))*DAMAS_Daily!E2*activation_mult_B)>=(power_mw*hours_per_day*damas_afrr_down*capacity_mult_B*stack_capacity*acceptance_rate+(MIN(DAMAS_Daily!D2*market_share_B*acceptance_rate*stack_activation,power_mw*hours_per_day,capacity_mwh))*DAMAS_Daily!F2*activation_mult_B),"aFRR+","aFRR-") | D2: =IF(C2="aFRR+",damas_afrr_up*capacity_mult_B,damas_afrr_down*capacity_mult_B) | E2: =acceptance_rate | F2: =IF(C2="aFRR+",power_mw*hours_per_day*damas_afrr_up*capacity_mult_B*stack_capacity*acceptance_rate,power_mw*hours_per_day*damas_afrr_down*capacity_mult_B*stack_capacity*acceptance_rate) | G2: =IF(C2="aFRR+",DAMAS_Daily!I2,DAMAS_Daily!J2) | H2: =IF(C2="aFRR+",DAMAS_Daily!E2,DAMAS_Daily!F2) | I2: =IF(C2="aFRR+",DAMAS_Daily!G2,DAMAS_Daily!H2) | J2: =IF(C2="aFRR+",DAMAS_Daily!C2,DAMAS_Daily!D2) | K2: =IF(C2="aFRR+",MIN(DAMAS_Daily!C2*market_share_B*acceptance_rate*stack_activation,power_mw*hours_per_day,capacity_mwh),MIN(DAMAS_Daily!D2*market_share_B*acceptance_rate*stack_activation,power_mw*hours_per_day,capacity_mwh)) | L2: =IF(K2>=capacity_mwh-0.01,"yes","no") | M2: =IF(C2="aFRR+",(MIN(DAMAS_Daily!C2*market_share_B*acceptance_rate*stack_activation,power_mw*hours_per_day,capacity_mwh))*DAMAS_Daily!E2*activation_mult_B,(MIN(DAMAS_Daily!D2*market_share_B*acceptance_rate*stack_activation,power_mw*hours_per_day,capacity_mwh))*DAMAS_Daily!F2*activation_mult_B) | N2: =F2+M2
A3: =DAMAS_Daily!A3 | B3: =DAMAS_Daily!B3 | C3: =IF((power_mw*hours_per_day*damas_afrr_up*capacity_mult_B*stack_capacity*acceptance_rate+(MIN(DAMAS_Daily!C3*market_share_B*acceptance_rate*stack_activation,power_mw*hours_per_day,capacity_mwh))*DAMAS_Daily!E3*activation_mult_B)>=(power_mw*hours_per_day*damas_afrr_down*capacity_mult_B*stack_capacity*acceptance_rate+(MIN(DAMAS_Daily!D3*market_share_B*acceptance_rate*stack_activation,power_mw*hours_per_day,capacity_mwh))*DAMAS_Daily!F3*activation_mult_B),"aFRR+","aFRR-") | D3: =IF(C3="aFRR+",damas_afrr_up*capacity_mult_B,damas_afrr_down*capacity_mult_B) | E3: =acceptance_rate | F3: =IF(C3="aFRR+",power_mw*hours_per_day*damas_afrr_up*capacity_mult_B*stack_capacity*acceptance_rate,power_mw*hours_per_day*damas_afrr_down*capacity_mult_B*stack_capacity*acceptance_rate) | G3: =IF(C3="aFRR+",DAMAS_Daily!I3,DAMAS_Daily!J3) | H3: =IF(C3="aFRR+",DAMAS_Daily!E3,DAMAS_Daily!F3) | I3: =IF(C3="aFRR+",DAMAS_Daily!G3,DAMAS_Daily!H3) | J3: =IF(C3="aFRR+",DAMAS_Daily!C3,DAMAS_Daily!D3) | K3: =IF(C3="aFRR+",MIN(DAMAS_Daily!C3*market_share_B*acceptance_rate*stack_activation,power_mw*hours_per_day,capacity_mwh),MIN(DAMAS_Daily!D3*market_share_B*acceptance_rate*stack_activation,power_mw*hours_per_day,capacity_mwh)) | L3: =IF(K3>=capacity_mwh-0.01,"yes","no") | M3: =IF(C3="aFRR+",(MIN(DAMAS_Daily!C3*market_share_B*acceptance_rate*stack_activation,power_mw*hours_per_day,capacity_mwh))*DAMAS_Daily!E3*activation_mult_B,(MIN(DAMAS_Daily!D3*market_share_B*acceptance_rate*stack_activation,power_mw*hours_per_day,capacity_mwh))*DAMAS_Daily!F3*activation_mult_B) | N3: =F3+M3
A4: =DAMAS_Daily!A4 | B4: =DAMAS_Daily!B4 | C4: =IF((power_mw*hours_per_day*damas_afrr_up*capacity_mult_B*stack_capacity*acceptance_rate+(MIN(DAMAS_Daily!C4*market_share_B*acceptance_rate*stack_activation,power_mw*hours_per_day,capacity_mwh))*DAMAS_Daily!E4*activation_mult_B)>=(power_mw*hours_per_day*damas_afrr_down*capacity_mult_B*stack_capacity*acceptance_rate+(MIN(DAMAS_Daily!D4*market_share_B*acceptance_rate*stack_activation,power_mw*hours_per_day,capacity_mwh))*DAMAS_Daily!F4*activation_mult_B),"aFRR+","aFRR-") | D4: =IF(C4="aFRR+",damas_afrr_up*capacity_mult_B,damas_afrr_down*capacity_mult_B) | E4: =acceptance_rate | F4: =IF(C4="aFRR+",power_mw*hours_per_day*damas_afrr_up*capacity_mult_B*stack_capacity*acceptance_rate,power_mw*hours_per_day*damas_afrr_down*capacity_mult_B*stack_capacity*acceptance_rate) | G4: =IF(C4="aFRR+",DAMAS_Daily!I4,DAMAS_Daily!J4) | H4: =IF(C4="aFRR+",DAMAS_Daily!E4,DAMAS_Daily!F4) | I4: =IF(C4="aFRR+",DAMAS_Daily!G4,DAMAS_Daily!H4) | J4: =IF(C4="aFRR+",DAMAS_Daily!C4,DAMAS_Daily!D4) | K4: =IF(C4="aFRR+",MIN(DAMAS_Daily!C4*market_share_B*acceptance_rate*stack_activation,power_mw*hours_per_day,capacity_mwh),MIN(DAMAS_Daily!D4*market_share_B*acceptance_rate*stack_activation,power_mw*hours_per_day,capacity_mwh)) | L4: =IF(K4>=capacity_mwh-0.01,"yes","no") | M4: =IF(C4="aFRR+",(MIN(DAMAS_Daily!C4*market_share_B*acceptance_rate*stack_activation,power_mw*hours_per_day,capacity_mwh))*DAMAS_Daily!E4*activation_mult_B,(MIN(DAMAS_Daily!D4*market_share_B*acceptance_rate*stack_activation,power_mw*hours_per_day,capacity_mwh))*DAMAS_Daily!F4*activation_mult_B) | N4: =F4+M4
A5: =DAMAS_Daily!A5 | B5: =DAMAS_Daily!B5 | C5: =IF((power_mw*hours_per_day*damas_afrr_up*capacity_mult_B*stack_capacity*acceptance_rate+(MIN(DAMAS_Daily!C5*market_share_B*acceptance_rate*stack_activation,power_mw*hours_per_day,capacity_mwh))*DAMAS_Daily!E5*activation_mult_B)>=(power_mw*hours_per_day*damas_afrr_down*capacity_mult_B*stack_capacity*acceptance_rate+(MIN(DAMAS_Daily!D5*market_share_B*acceptance_rate*stack_activation,power_mw*hours_per_day,capacity_mwh))*DAMAS_Daily!F5*activation_mult_B),"aFRR+","aFRR-") | D5: =IF(C5="aFRR+",damas_afrr_up*capacity_mult_B,damas_afrr_down*capacity_mult_B) | E5: =acceptance_rate | F5: =IF(C5="aFRR+",power_mw*hours_per_day*damas_afrr_up*capacity_mult_B*stack_capacity*acceptance_rate,power_mw*hours_per_day*damas_afrr_down*capacity_mult_B*stack_capacity*acceptance_rate) | G5: =IF(C5="aFRR+",DAMAS_Daily!I5,DAMAS_Daily!J5) | H5: =IF(C5="aFRR+",DAMAS_Daily!E5,DAMAS_Daily!F5) | I5: =IF(C5="aFRR+",DAMAS_Daily!G5,DAMAS_Daily!H5) | J5: =IF(C5="aFRR+",DAMAS_Daily!C5,DAMAS_Daily!D5) | K5: =IF(C5="aFRR+",MIN(DAMAS_Daily!C5*market_share_B*acceptance_rate*stack_activation,power_mw*hours_per_day,capacity_mwh),MIN(DAMAS_Daily!D5*market_share_B*acceptance_rate*stack_activation,power_mw*hours_per_day,capacity_mwh)) | L5: =IF(K5>=capacity_mwh-0.01,"yes","no") | M5: =IF(C5="aFRR+",(MIN(DAMAS_Daily!C5*market_share_B*acceptance_rate*stack_activation,power_mw*hours_per_day,capacity_mwh))*DAMAS_Daily!E5*activation_mult_B,(MIN(DAMAS_Daily!D5*market_share_B*acceptance_rate*stack_activation,power_mw*hours_per_day,capacity_mwh))*DAMAS_Daily!F5*activation_mult_B) | N5: =F5+M5
A6: =DAMAS_Daily!A6 | B6: =DAMAS_Daily!B6 | C6: =IF((power_mw*hours_per_day*damas_afrr_up*capacity_mult_B*stack_capacity*acceptance_rate+(MIN(DAMAS_Daily!C6*market_share_B*acceptance_rate*stack_activation,power_mw*hours_per_day,capacity_mwh))*DAMAS_Daily!E6*activation_mult_B)>=(power_mw*hours_per_day*damas_afrr_down*capacity_mult_B*stack_capacity*acceptance_rate+(MIN(DAMAS_Daily!D6*market_share_B*acceptance_rate*stack_activation,power_mw*hours_per_day,capacity_mwh))*DAMAS_Daily!F6*activation_mult_B),"aFRR+","aFRR-") | D6: =IF(C6="aFRR+",damas_afrr_up*capacity_mult_B,damas_afrr_down*capacity_mult_B) | E6: =acceptance_rate | F6: =IF(C6="aFRR+",power_mw*hours_per_day*damas_afrr_up*capacity_mult_B*stack_capacity*acceptance_rate,power_mw*hours_per_day*damas_afrr_down*capacity_mult_B*stack_capacity*acceptance_rate) | G6: =IF(C6="aFRR+",DAMAS_Daily!I6,DAMAS_Daily!J6) | H6: =IF(C6="aFRR+",DAMAS_Daily!E6,DAMAS_Daily!F6) | I6: =IF(C6="aFRR+",DAMAS_Daily!G6,DAMAS_Daily!H6) | J6: =IF(C6="aFRR+",DAMAS_Daily!C6,DAMAS_Daily!D6) | K6: =IF(C6="aFRR+",MIN(DAMAS_Daily!C6*market_share_B*acceptance_rate*stack_activation,power_mw*hours_per_day,capacity_mwh),MIN(DAMAS_Daily!D6*market_share_B*acceptance_rate*stack_activation,power_mw*hours_per_day,capacity_mwh)) | L6: =IF(K6>=capacity_mwh-0.01,"yes","no") | M6: =IF(C6="aFRR+",(MIN(DAMAS_Daily!C6*market_share_B*acceptance_rate*stack_activation,power_mw*hours_per_day,capacity_mwh))*DAMAS_Daily!E6*activation_mult_B,(MIN(DAMAS_Daily!D6*market_share_B*acceptance_rate*stack_activation,power_mw*hours_per_day,capacity_mwh))*DAMAS_Daily!F6*activation_mult_B) | N6: =F6+M6
A7: =DAMAS_Daily!A7 | B7: =DAMAS_Daily!B7 | C7: =IF((power_mw*hours_per_day*damas_afrr_up*capacity_mult_B*stack_capacity*acceptance_rate+(MIN(DAMAS_Daily!C7*market_share_B*acceptance_rate*stack_activation,power_mw*hours_per_day,capacity_mwh))*DAMAS_Daily!E7*activation_mult_B)>=(power_mw*hours_per_day*damas_afrr_down*capacity_mult_B*stack_capacity*acceptance_rate+(MIN(DAMAS_Daily!D7*market_share_B*acceptance_rate*stack_activation,power_mw*hours_per_day,capacity_mwh))*DAMAS_Daily!F7*activation_mult_B),"aFRR+","aFRR-") | D7: =IF(C7="aFRR+",damas_afrr_up*capacity_mult_B,damas_afrr_down*capacity_mult_B) | E7: =acceptance_rate | F7: =IF(C7="aFRR+",power_mw*hours_per_day*damas_afrr_up*capacity_mult_B*stack_capacity*acceptance_rate,power_mw*hours_per_day*damas_afrr_down*capacity_mult_B*stack_capacity*acceptance_rate) | G7: =IF(C7="aFRR+",DAMAS_Daily!I7,DAMAS_Daily!J7) | H7: =IF(C7="aFRR+",DAMAS_Daily!E7,DAMAS_Daily!F7) | I7: =IF(C7="aFRR+",DAMAS_Daily!G7,DAMAS_Daily!H7) | J7: =IF(C7="aFRR+",DAMAS_Daily!C7,DAMAS_Daily!D7) | K7: =IF(C7="aFRR+",MIN(DAMAS_Daily!C7*market_share_B*acceptance_rate*stack_activation,power_mw*hours_per_day,capacity_mwh),MIN(DAMAS_Daily!D7*market_share_B*acceptance_rate*stack_activation,power_mw*hours_per_day,capacity_mwh)) | L7: =IF(K7>=capacity_mwh-0.01,"yes","no") | M7: =IF(C7="aFRR+",(MIN(DAMAS_Daily!C7*market_share_B*acceptance_rate*stack_activation,power_mw*hours_per_day,capacity_mwh))*DAMAS_Daily!E7*activation_mult_B,(MIN(DAMAS_Daily!D7*market_share_B*acceptance_rate*stack_activation,power_mw*hours_per_day,capacity_mwh))*DAMAS_Daily!F7*activation_mult_B) | N7: =F7+M7
A8: =DAMAS_Daily!A8 | B8: =DAMAS_Daily!B8 | C8: =IF((power_mw*hours_per_day*damas_afrr_up*capacity_mult_B*stack_capacity*acceptance_rate+(MIN(DAMAS_Daily!C8*market_share_B*acceptance_rate*stack_activation,power_mw*hours_per_day,capacity_mwh))*DAMAS_Daily!E8*activation_mult_B)>=(power_mw*hours_per_day*damas_afrr_down*capacity_mult_B*stack_capacity*acceptance_rate+(MIN(DAMAS_Daily!D8*market_share_B*acceptance_rate*stack_activation,power_mw*hours_per_day,capacity_mwh))*DAMAS_Daily!F8*activation_mult_B),"aFRR+","aFRR-") | D8: =IF(C8="aFRR+",damas_afrr_up*capacity_mult_B,damas_afrr_down*capacity_mult_B) | E8: =acceptance_rate | F8: =IF(C8="aFRR+",power_mw*hours_per_day*damas_afrr_up*capacity_mult_B*stack_capacity*acceptance_rate,power_mw*hours_per_day*damas_afrr_down*capacity_mult_B*stack_capacity*acceptance_rate) | G8: =IF(C8="aFRR+",DAMAS_Daily!I8,DAMAS_Daily!J8) | H8: =IF(C8="aFRR+",DAMAS_Daily!E8,DAMAS_Daily!F8) | I8: =IF(C8="aFRR+",DAMAS_Daily!G8,DAMAS_Daily!H8) | J8: =IF(C8="aFRR+",DAMAS_Daily!C8,DAMAS_Daily!D8) | K8: =IF(C8="aFRR+",MIN(DAMAS_Daily!C8*market_share_B*acceptance_rate*stack_activation,power_mw*hours_per_day,capacity_mwh),MIN(DAMAS_Daily!D8*market_share_B*acceptance_rate*stack_activation,power_mw*hours_per_day,capacity_mwh)) | L8: =IF(K8>=capacity_mwh-0.01,"yes","no") | M8: =IF(C8="aFRR+",(MIN(DAMAS_Daily!C8*market_share_B*acceptance_rate*stack_activation,power_mw*hours_per_day,capacity_mwh))*DAMAS_Daily!E8*activation_mult_B,(MIN(DAMAS_Daily!D8*market_share_B*acceptance_rate*stack_activation,power_mw*hours_per_day,capacity_mwh))*DAMAS_Daily!F8*activation_mult_B) | N8: =F8+M8
A9: =DAMAS_Daily!A9 | B9: =DAMAS_Daily!B9 | C9: =IF((power_mw*hours_per_day*damas_afrr_up*capacity_mult_B*stack_capacity*acceptance_rate+(MIN(DAMAS_Daily!C9*market_share_B*acceptance_rate*stack_activation,power_mw*hours_per_day,capacity_mwh))*DAMAS_Daily!E9*activation_mult_B)>=(power_mw*hours_per_day*damas_afrr_down*capacity_mult_B*stack_capacity*acceptance_rate+(MIN(DAMAS_Daily!D9*market_share_B*acceptance_rate*stack_activation,power_mw*hours_per_day,capacity_mwh))*DAMAS_Daily!F9*activation_mult_B),"aFRR+","aFRR-") | D9: =IF(C9="aFRR+",damas_afrr_up*capacity_mult_B,damas_afrr_down*capacity_mult_B) | E9: =acceptance_rate | F9: =IF(C9="aFRR+",power_mw*hours_per_day*damas_afrr_up*capacity_mult_B*stack_capacity*acceptance_rate,power_mw*hours_per_day*damas_afrr_down*capacity_mult_B*stack_capacity*acceptance_rate) | G9: =IF(C9="aFRR+",DAMAS_Daily!I9,DAMAS_Daily!J9) | H9: =IF(C9="aFRR+",DAMAS_Daily!E9,DAMAS_Daily!F9) | I9: =IF(C9="aFRR+",DAMAS_Daily!G9,DAMAS_Daily!H9) | J9: =IF(C9="aFRR+",DAMAS_Daily!C9,DAMAS_Daily!D9) | K9: =IF(C9="aFRR+",MIN(DAMAS_Daily!C9*market_share_B*acceptance_rate*stack_activation,power_mw*hours_per_day,capacity_mwh),MIN(DAMAS_Daily!D9*market_share_B*acceptance_rate*stack_activation,power_mw*hours_per_day,capacity_mwh)) | L9: =IF(K9>=capacity_mwh-0.01,"yes","no") | M9: =IF(C9="aFRR+",(MIN(DAMAS_Daily!C9*market_share_B*acceptance_rate*stack_activation,power_mw*hours_per_day,capacity_mwh))*DAMAS_Daily!E9*activation_mult_B,(MIN(DAMAS_Daily!D9*market_share_B*acceptance_rate*stack_activation,power_mw*hours_per_day,capacity_mwh))*DAMAS_Daily!F9*activation_mult_B) | N9: =F9+M9
A10: =DAMAS_Daily!A10 | B10: =DAMAS_Daily!B10 | C10: =IF((power_mw*hours_per_day*damas_afrr_up*capacity_mult_B*stack_capacity*acceptance_rate+(MIN(DAMAS_Daily!C10*market_share_B*acceptance_rate*stack_activation,power_mw*hours_per_day,capacity_mwh))*DAMAS_Daily!E10*activation_mult_B)>=(power_mw*hours_per_day*damas_afrr_down*capacity_mult_B*stack_capacity*acceptance_rate+(MIN(DAMAS_Daily!D10*market_share_B*acceptance_rate*stack_activation,power_mw*hours_per_day,capacity_mwh))*DAMAS_Daily!F10*activation_mult_B),"aFRR+","aFRR-") | D10: =IF(C10="aFRR+",damas_afrr_up*capacity_mult_B,damas_afrr_down*capacity_mult_B) | E10: =acceptance_rate | F10: =IF(C10="aFRR+",power_mw*hours_per_day*damas_afrr_up*capacity_mult_B*stack_capacity*acceptance_rate,power_mw*hours_per_day*damas_afrr_down*capacity_mult_B*stack_capacity*acceptance_rate) | G10: =IF(C10="aFRR+",DAMAS_Daily!I10,DAMAS_Daily!J10) | H10: =IF(C10="aFRR+",DAMAS_Daily!E10,DAMAS_Daily!F10) | I10: =IF(C10="aFRR+",DAMAS_Daily!G10,DAMAS_Daily!H10) | J10: =IF(C10="aFRR+",DAMAS_Daily!C10,DAMAS_Daily!D10) | K10: =IF(C10="aFRR+",MIN(DAMAS_Daily!C10*market_share_B*acceptance_rate*stack_activation,power_mw*hours_per_day,capacity_mwh),MIN(DAMAS_Daily!D10*market_share_B*acceptance_rate*stack_activation,power_mw*hours_per_day,capacity_mwh)) | L10: =IF(K10>=capacity_mwh-0.01,"yes","no") | M10: =IF(C10="aFRR+",(MIN(DAMAS_Daily!C10*market_share_B*acceptance_rate*stack_activation,power_mw*hours_per_day,capacity_mwh))*DAMAS_Daily!E10*activation_mult_B,(MIN(DAMAS_Daily!D10*market_share_B*acceptance_rate*stack_activation,power_mw*hours_per_day,capacity_mwh))*DAMAS_Daily!F10*activation_mult_B) | N10: =F10+M10
A11: =DAMAS_Daily!A11 | B11: =DAMAS_Daily!B11 | C11: =IF((power_mw*hours_per_day*damas_afrr_up*capacity_mult_B*stack_capacity*acceptance_rate+(MIN(DAMAS_Daily!C11*market_share_B*acceptance_rate*stack_activation,power_mw*hours_per_day,capacity_mwh))*DAMAS_Daily!E11*activation_mult_B)>=(power_mw*hours_per_day*damas_afrr_down*capacity_mult_B*stack_capacity*acceptance_rate+(MIN(DAMAS_Daily!D11*market_share_B*acceptance_rate*stack_activation,power_mw*hours_per_day,capacity_mwh))*DAMAS_Daily!F11*activation_mult_B),"aFRR+","aFRR-") | D11: =IF(C11="aFRR+",damas_afrr_up*capacity_mult_B,damas_afrr_down*capacity_mult_B) | E11: =acceptance_rate | F11: =IF(C11="aFRR+",power_mw*hours_per_day*damas_afrr_up*capacity_mult_B*stack_capacity*acceptance_rate,power_mw*hours_per_day*damas_afrr_down*capacity_mult_B*stack_capacity*acceptance_rate) | G11: =IF(C11="aFRR+",DAMAS_Daily!I11,DAMAS_Daily!J11) | H11: =IF(C11="aFRR+",DAMAS_Daily!E11,DAMAS_Daily!F11) | I11: =IF(C11="aFRR+",DAMAS_Daily!G11,DAMAS_Daily!H11) | J11: =IF(C11="aFRR+",DAMAS_Daily!C11,DAMAS_Daily!D11) | K11: =IF(C11="aFRR+",MIN(DAMAS_Daily!C11*market_share_B*acceptance_rate*stack_activation,power_mw*hours_per_day,capacity_mwh),MIN(DAMAS_Daily!D11*market_share_B*acceptance_rate*stack_activation,power_mw*hours_per_day,capacity_mwh)) | L11: =IF(K11>=capacity_mwh-0.01,"yes","no") | M11: =IF(C11="aFRR+",(MIN(DAMAS_Daily!C11*market_share_B*acceptance_rate*stack_activation,power_mw*hours_per_day,capacity_mwh))*DAMAS_Daily!E11*activation_mult_B,(MIN(DAMAS_Daily!D11*market_share_B*acceptance_rate*stack_activation,power_mw*hours_per_day,capacity_mwh))*DAMAS_Daily!F11*activation_mult_B) | N11: =F11+M11
A12: =DAMAS_Daily!A12 | B12: =DAMAS_Daily!B12 | C12: =IF((power_mw*hours_per_day*damas_afrr_up*capacity_mult_B*stack_capacity*acceptance_rate+(MIN(DAMAS_Daily!C12*market_share_B*acceptance_rate*stack_activation,power_mw*hours_per_day,capacity_mwh))*DAMAS_Daily!E12*activation_mult_B)>=(power_mw*hours_per_day*damas_afrr_down*capacity_mult_B*stack_capacity*acceptance_rate+(MIN(DAMAS_Daily!D12*market_share_B*acceptance_rate*stack_activation,power_mw*hours_per_day,capacity_mwh))*DAMAS_Daily!F12*activation_mult_B),"aFRR+","aFRR-") | D12: =IF(C12="aFRR+",damas_afrr_up*capacity_mult_B,damas_afrr_down*capacity_mult_B) | E12: =acceptance_rate | F12: =IF(C12="aFRR+",power_mw*hours_per_day*damas_afrr_up*capacity_mult_B*stack_capacity*acceptance_rate,power_mw*hours_per_day*damas_afrr_down*capacity_mult_B*stack_capacity*acceptance_rate) | G12: =IF(C12="aFRR+",DAMAS_Daily!I12,DAMAS_Daily!J12) | H12: =IF(C12="aFRR+",DAMAS_Daily!E12,DAMAS_Daily!F12) | I12: =IF(C12="aFRR+",DAMAS_Daily!G12,DAMAS_Daily!H12) | J12: =IF(C12="aFRR+",DAMAS_Daily!C12,DAMAS_Daily!D12) | K12: =IF(C12="aFRR+",MIN(DAMAS_Daily!C12*market_share_B*acceptance_rate*stack_activation,power_mw*hours_per_day,capacity_mwh),MIN(DAMAS_Daily!D12*market_share_B*acceptance_rate*stack_activation,power_mw*hours_per_day,capacity_mwh)) | L12: =IF(K12>=capacity_mwh-0.01,"yes","no") | M12: =IF(C12="aFRR+",(MIN(DAMAS_Daily!C12*market_share_B*acceptance_rate*stack_activation,power_mw*hours_per_day,capacity_mwh))*DAMAS_Daily!E12*activation_mult_B,(MIN(DAMAS_Daily!D12*market_share_B*acceptance_rate*stack_activation,power_mw*hours_per_day,capacity_mwh))*DAMAS_Daily!F12*activation_mult_B) | N12: =F12+M12
A13: =DAMAS_Daily!A13 | B13: =DAMAS_Daily!B13 | C13: =IF((power_mw*hours_per_day*damas_afrr_up*capacity_mult_B*stack_capacity*acceptance_rate+(MIN(DAMAS_Daily!C13*market_share_B*acceptance_rate*stack_activation,power_mw*hours_per_day,capacity_mwh))*DAMAS_Daily!E13*activation_mult_B)>=(power_mw*hours_per_day*damas_afrr_down*capacity_mult_B*stack_capacity*acceptance_rate+(MIN(DAMAS_Daily!D13*market_share_B*acceptance_rate*stack_activation,power_mw*hours_per_day,capacity_mwh))*DAMAS_Daily!F13*activation_mult_B),"aFRR+","aFRR-") | D13: =IF(C13="aFRR+",damas_afrr_up*capacity_mult_B,damas_afrr_down*capacity_mult_B) | E13: =acceptance_rate | F13: =IF(C13="aFRR+",power_mw*hours_per_day*damas_afrr_up*capacity_mult_B*stack_capacity*acceptance_rate,power_mw*hours_per_day*damas_afrr_down*capacity_mult_B*stack_capacity*acceptance_rate) | G13: =IF(C13="aFRR+",DAMAS_Daily!I13,DAMAS_Daily!J13) | H13: =IF(C13="aFRR+",DAMAS_Daily!E13,DAMAS_Daily!F13) | I13: =IF(C13="aFRR+",DAMAS_Daily!G13,DAMAS_Daily!H13) | J13: =IF(C13="aFRR+",DAMAS_Daily!C13,DAMAS_Daily!D13) | K13: =IF(C13="aFRR+",MIN(DAMAS_Daily!C13*market_share_B*acceptance_rate*stack_activation,power_mw*hours_per_day,capacity_mwh),MIN(DAMAS_Daily!D13*market_share_B*acceptance_rate*stack_activation,power_mw*hours_per_day,capacity_mwh)) | L13: =IF(K13>=capacity_mwh-0.01,"yes","no") | M13: =IF(C13="aFRR+",(MIN(DAMAS_Daily!C13*market_share_B*acceptance_rate*stack_activation,power_mw*hours_per_day,capacity_mwh))*DAMAS_Daily!E13*activation_mult_B,(MIN(DAMAS_Daily!D13*market_share_B*acceptance_rate*stack_activation,power_mw*hours_per_day,capacity_mwh))*DAMAS_Daily!F13*activation_mult_B) | N13: =F13+M13
... A367: =DAMAS_Daily!A367 | B367: =DAMAS_Daily!B367 | C367: =IF((power_mw*hours_per_day*damas_afrr_up*capacity_mult_B*stack_capacity*acceptance_rate+(MIN(DAMAS_Daily!C367*market_share_B*acceptance_rate*stack_activation,power_mw*hours_per_day,capacity_mwh))*DAMAS_Daily!E367*activation_mult_B)>=(power_mw*hours_per_day*damas_afrr_down*capacity_mult_B*stack_capacity*acceptance_rate+(MIN(DAMAS_Daily!D367*market_share_B*acceptance_rate*stack_activation,power_mw*hours_per_day,capacity_mwh))*DAMAS_Daily!F367*activation_mult_B),"aFRR+","aFRR-") | D367: =IF(C367="aFRR+",damas_afrr_up*capacity_mult_B,damas_afrr_down*capacity_mult_B) | E367: =acceptance_rate | F367: =IF(C367="aFRR+",power_mw*hours_per_day*damas_afrr_up*capacity_mult_B*stack_capacity*acceptance_rate,power_mw*hours_per_day*damas_afrr_down*capacity_mult_B*stack_capacity*acceptance_rate) | G367: =IF(C367="aFRR+",DAMAS_Daily!I367,DAMAS_Daily!J367) | H367: =IF(C367="aFRR+",DAMAS_Daily!E367,DAMAS_Daily!F367) | I367: =IF(C367="aFRR+",DAMAS_Daily!G367,DAMAS_Daily!H367) | J367: =IF(C367="aFRR+",DAMAS_Daily!C367,DAMAS_Daily!D367) | K367: =IF(C367="aFRR+",MIN(DAMAS_Daily!C367*market_share_B*acceptance_rate*stack_activation,power_mw*hours_per_day,capacity_mwh),MIN(DAMAS_Daily!D367*market_share_B*acceptance_rate*stack_activation,power_mw*hours_per_day,capacity_mwh)) | L367: =IF(K367>=capacity_mwh-0.01,"yes","no") | M367: =IF(C367="aFRR+",(MIN(DAMAS_Daily!C367*market_share_B*acceptance_rate*stack_activation,power_mw*hours_per_day,capacity_mwh))*DAMAS_Daily!E367*activation_mult_B,(MIN(DAMAS_Daily!D367*market_share_B*acceptance_rate*stack_activation,power_mw*hours_per_day,capacity_mwh))*DAMAS_Daily!F367*activation_mult_B) | N367: =F367+M367
A368: TOTAL | B368: 366 days | C368: — | F368: =SUM(F2:F367) | G368: =SUM(G2:G367) | K368: =SUM(K2:K367) | M368: =SUM(M2:M367) | N368: =SUM(N2:N367)

Sheet Scenario_C_Mature
A1: Date | B1: Weekday | C1: Selected | D1: Recommended bid (€/MW/h) | E1: Acceptance rate | F1: Capacity revenue (€) | G1: Slots activated (#/96) | H1: Avg activation price (€/MWh) | I1: Max activation price (€/MWh) | J1: Market activations (MWh) | K1: Captured energy (MWh) | L1: Battery cap binding | M1: Activation revenue (€) | N1: Daily revenue (€)
A2: =DAMAS_Daily!A2 | B2: =DAMAS_Daily!B2 | C2: =IF((power_mw*hours_per_day*damas_afrr_up*capacity_mult_C*stack_capacity*acceptance_rate+(MIN(DAMAS_Daily!C2*market_share_C*acceptance_rate*stack_activation,power_mw*hours_per_day,capacity_mwh))*DAMAS_Daily!E2*activation_mult_C)>=(power_mw*hours_per_day*damas_afrr_down*capacity_mult_C*stack_capacity*acceptance_rate+(MIN(DAMAS_Daily!D2*market_share_C*acceptance_rate*stack_activation,power_mw*hours_per_day,capacity_mwh))*DAMAS_Daily!F2*activation_mult_C),"aFRR+","aFRR-") | D2: =IF(C2="aFRR+",damas_afrr_up*capacity_mult_C,damas_afrr_down*capacity_mult_C) | E2: =acceptance_rate | F2: =IF(C2="aFRR+",power_mw*hours_per_day*damas_afrr_up*capacity_mult_C*stack_capacity*acceptance_rate,power_mw*hours_per_day*damas_afrr_down*capacity_mult_C*stack_capacity*acceptance_rate) | G2: =IF(C2="aFRR+",DAMAS_Daily!I2,DAMAS_Daily!J2) | H2: =IF(C2="aFRR+",DAMAS_Daily!E2,DAMAS_Daily!F2) | I2: =IF(C2="aFRR+",DAMAS_Daily!G2,DAMAS_Daily!H2) | J2: =IF(C2="aFRR+",DAMAS_Daily!C2,DAMAS_Daily!D2) | K2: =IF(C2="aFRR+",MIN(DAMAS_Daily!C2*market_share_C*acceptance_rate*stack_activation,power_mw*hours_per_day,capacity_mwh),MIN(DAMAS_Daily!D2*market_share_C*acceptance_rate*stack_activation,power_mw*hours_per_day,capacity_mwh)) | L2: =IF(K2>=capacity_mwh-0.01,"yes","no") | M2: =IF(C2="aFRR+",(MIN(DAMAS_Daily!C2*market_share_C*acceptance_rate*stack_activation,power_mw*hours_per_day,capacity_mwh))*DAMAS_Daily!E2*activation_mult_C,(MIN(DAMAS_Daily!D2*market_share_C*acceptance_rate*stack_activation,power_mw*hours_per_day,capacity_mwh))*DAMAS_Daily!F2*activation_mult_C) | N2: =F2+M2
A3: =DAMAS_Daily!A3 | B3: =DAMAS_Daily!B3 | C3: =IF((power_mw*hours_per_day*damas_afrr_up*capacity_mult_C*stack_capacity*acceptance_rate+(MIN(DAMAS_Daily!C3*market_share_C*acceptance_rate*stack_activation,power_mw*hours_per_day,capacity_mwh))*DAMAS_Daily!E3*activation_mult_C)>=(power_mw*hours_per_day*damas_afrr_down*capacity_mult_C*stack_capacity*acceptance_rate+(MIN(DAMAS_Daily!D3*market_share_C*acceptance_rate*stack_activation,power_mw*hours_per_day,capacity_mwh))*DAMAS_Daily!F3*activation_mult_C),"aFRR+","aFRR-") | D3: =IF(C3="aFRR+",damas_afrr_up*capacity_mult_C,damas_afrr_down*capacity_mult_C) | E3: =acceptance_rate | F3: =IF(C3="aFRR+",power_mw*hours_per_day*damas_afrr_up*capacity_mult_C*stack_capacity*acceptance_rate,power_mw*hours_per_day*damas_afrr_down*capacity_mult_C*stack_capacity*acceptance_rate) | G3: =IF(C3="aFRR+",DAMAS_Daily!I3,DAMAS_Daily!J3) | H3: =IF(C3="aFRR+",DAMAS_Daily!E3,DAMAS_Daily!F3) | I3: =IF(C3="aFRR+",DAMAS_Daily!G3,DAMAS_Daily!H3) | J3: =IF(C3="aFRR+",DAMAS_Daily!C3,DAMAS_Daily!D3) | K3: =IF(C3="aFRR+",MIN(DAMAS_Daily!C3*market_share_C*acceptance_rate*stack_activation,power_mw*hours_per_day,capacity_mwh),MIN(DAMAS_Daily!D3*market_share_C*acceptance_rate*stack_activation,power_mw*hours_per_day,capacity_mwh)) | L3: =IF(K3>=capacity_mwh-0.01,"yes","no") | M3: =IF(C3="aFRR+",(MIN(DAMAS_Daily!C3*market_share_C*acceptance_rate*stack_activation,power_mw*hours_per_day,capacity_mwh))*DAMAS_Daily!E3*activation_mult_C,(MIN(DAMAS_Daily!D3*market_share_C*acceptance_rate*stack_activation,power_mw*hours_per_day,capacity_mwh))*DAMAS_Daily!F3*activation_mult_C) | N3: =F3+M3
A4: =DAMAS_Daily!A4 | B4: =DAMAS_Daily!B4 | C4: =IF((power_mw*hours_per_day*damas_afrr_up*capacity_mult_C*stack_capacity*acceptance_rate+(MIN(DAMAS_Daily!C4*market_share_C*acceptance_rate*stack_activation,power_mw*hours_per_day,capacity_mwh))*DAMAS_Daily!E4*activation_mult_C)>=(power_mw*hours_per_day*damas_afrr_down*capacity_mult_C*stack_capacity*acceptance_rate+(MIN(DAMAS_Daily!D4*market_share_C*acceptance_rate*stack_activation,power_mw*hours_per_day,capacity_mwh))*DAMAS_Daily!F4*activation_mult_C),"aFRR+","aFRR-") | D4: =IF(C4="aFRR+",damas_afrr_up*capacity_mult_C,damas_afrr_down*capacity_mult_C) | E4: =acceptance_rate | F4: =IF(C4="aFRR+",power_mw*hours_per_day*damas_afrr_up*capacity_mult_C*stack_capacity*acceptance_rate,power_mw*hours_per_day*damas_afrr_down*capacity_mult_C*stack_capacity*acceptance_rate) | G4: =IF(C4="aFRR+",DAMAS_Daily!I4,DAMAS_Daily!J4) | H4: =IF(C4="aFRR+",DAMAS_Daily!E4,DAMAS_Daily!F4) | I4: =IF(C4="aFRR+",DAMAS_Daily!G4,DAMAS_Daily!H4) | J4: =IF(C4="aFRR+",DAMAS_Daily!C4,DAMAS_Daily!D4) | K4: =IF(C4="aFRR+",MIN(DAMAS_Daily!C4*market_share_C*acceptance_rate*stack_activation,power_mw*hours_per_day,capacity_mwh),MIN(DAMAS_Daily!D4*market_share_C*acceptance_rate*stack_activation,power_mw*hours_per_day,capacity_mwh)) | L4: =IF(K4>=capacity_mwh-0.01,"yes","no") | M4: =IF(C4="aFRR+",(MIN(DAMAS_Daily!C4*market_share_C*acceptance_rate*stack_activation,power_mw*hours_per_day,capacity_mwh))*DAMAS_Daily!E4*activation_mult_C,(MIN(DAMAS_Daily!D4*market_share_C*acceptance_rate*stack_activation,power_mw*hours_per_day,capacity_mwh))*DAMAS_Daily!F4*activation_mult_C) | N4: =F4+M4
A5: =DAMAS_Daily!A5 | B5: =DAMAS_Daily!B5 | C5: =IF((power_mw*hours_per_day*damas_afrr_up*capacity_mult_C*stack_capacity*acceptance_rate+(MIN(DAMAS_Daily!C5*market_share_C*acceptance_rate*stack_activation,power_mw*hours_per_day,capacity_mwh))*DAMAS_Daily!E5*activation_mult_C)>=(power_mw*hours_per_day*damas_afrr_down*capacity_mult_C*stack_capacity*acceptance_rate+(MIN(DAMAS_Daily!D5*market_share_C*acceptance_rate*stack_activation,power_mw*hours_per_day,capacity_mwh))*DAMAS_Daily!F5*activation_mult_C),"aFRR+","aFRR-") | D5: =IF(C5="aFRR+",damas_afrr_up*capacity_mult_C,damas_afrr_down*capacity_mult_C) | E5: =acceptance_rate | F5: =IF(C5="aFRR+",power_mw*hours_per_day*damas_afrr_up*capacity_mult_C*stack_capacity*acceptance_rate,power_mw*hours_per_day*damas_afrr_down*capacity_mult_C*stack_capacity*acceptance_rate) | G5: =IF(C5="aFRR+",DAMAS_Daily!I5,DAMAS_Daily!J5) | H5: =IF(C5="aFRR+",DAMAS_Daily!E5,DAMAS_Daily!F5) | I5: =IF(C5="aFRR+",DAMAS_Daily!G5,DAMAS_Daily!H5) | J5: =IF(C5="aFRR+",DAMAS_Daily!C5,DAMAS_Daily!D5) | K5: =IF(C5="aFRR+",MIN(DAMAS_Daily!C5*market_share_C*acceptance_rate*stack_activation,power_mw*hours_per_day,capacity_mwh),MIN(DAMAS_Daily!D5*market_share_C*acceptance_rate*stack_activation,power_mw*hours_per_day,capacity_mwh)) | L5: =IF(K5>=capacity_mwh-0.01,"yes","no") | M5: =IF(C5="aFRR+",(MIN(DAMAS_Daily!C5*market_share_C*acceptance_rate*stack_activation,power_mw*hours_per_day,capacity_mwh))*DAMAS_Daily!E5*activation_mult_C,(MIN(DAMAS_Daily!D5*market_share_C*acceptance_rate*stack_activation,power_mw*hours_per_day,capacity_mwh))*DAMAS_Daily!F5*activation_mult_C) | N5: =F5+M5
A6: =DAMAS_Daily!A6 | B6: =DAMAS_Daily!B6 | C6: =IF((power_mw*hours_per_day*damas_afrr_up*capacity_mult_C*stack_capacity*acceptance_rate+(MIN(DAMAS_Daily!C6*market_share_C*acceptance_rate*stack_activation,power_mw*hours_per_day,capacity_mwh))*DAMAS_Daily!E6*activation_mult_C)>=(power_mw*hours_per_day*damas_afrr_down*capacity_mult_C*stack_capacity*acceptance_rate+(MIN(DAMAS_Daily!D6*market_share_C*acceptance_rate*stack_activation,power_mw*hours_per_day,capacity_mwh))*DAMAS_Daily!F6*activation_mult_C),"aFRR+","aFRR-") | D6: =IF(C6="aFRR+",damas_afrr_up*capacity_mult_C,damas_afrr_down*capacity_mult_C) | E6: =acceptance_rate | F6: =IF(C6="aFRR+",power_mw*hours_per_day*damas_afrr_up*capacity_mult_C*stack_capacity*acceptance_rate,power_mw*hours_per_day*damas_afrr_down*capacity_mult_C*stack_capacity*acceptance_rate) | G6: =IF(C6="aFRR+",DAMAS_Daily!I6,DAMAS_Daily!J6) | H6: =IF(C6="aFRR+",DAMAS_Daily!E6,DAMAS_Daily!F6) | I6: =IF(C6="aFRR+",DAMAS_Daily!G6,DAMAS_Daily!H6) | J6: =IF(C6="aFRR+",DAMAS_Daily!C6,DAMAS_Daily!D6) | K6: =IF(C6="aFRR+",MIN(DAMAS_Daily!C6*market_share_C*acceptance_rate*stack_activation,power_mw*hours_per_day,capacity_mwh),MIN(DAMAS_Daily!D6*market_share_C*acceptance_rate*stack_activation,power_mw*hours_per_day,capacity_mwh)) | L6: =IF(K6>=capacity_mwh-0.01,"yes","no") | M6: =IF(C6="aFRR+",(MIN(DAMAS_Daily!C6*market_share_C*acceptance_rate*stack_activation,power_mw*hours_per_day,capacity_mwh))*DAMAS_Daily!E6*activation_mult_C,(MIN(DAMAS_Daily!D6*market_share_C*acceptance_rate*stack_activation,power_mw*hours_per_day,capacity_mwh))*DAMAS_Daily!F6*activation_mult_C) | N6: =F6+M6
A7: =DAMAS_Daily!A7 | B7: =DAMAS_Daily!B7 | C7: =IF((power_mw*hours_per_day*damas_afrr_up*capacity_mult_C*stack_capacity*acceptance_rate+(MIN(DAMAS_Daily!C7*market_share_C*acceptance_rate*stack_activation,power_mw*hours_per_day,capacity_mwh))*DAMAS_Daily!E7*activation_mult_C)>=(power_mw*hours_per_day*damas_afrr_down*capacity_mult_C*stack_capacity*acceptance_rate+(MIN(DAMAS_Daily!D7*market_share_C*acceptance_rate*stack_activation,power_mw*hours_per_day,capacity_mwh))*DAMAS_Daily!F7*activation_mult_C),"aFRR+","aFRR-") | D7: =IF(C7="aFRR+",damas_afrr_up*capacity_mult_C,damas_afrr_down*capacity_mult_C) | E7: =acceptance_rate | F7: =IF(C7="aFRR+",power_mw*hours_per_day*damas_afrr_up*capacity_mult_C*stack_capacity*acceptance_rate,power_mw*hours_per_day*damas_afrr_down*capacity_mult_C*stack_capacity*acceptance_rate) | G7: =IF(C7="aFRR+",DAMAS_Daily!I7,DAMAS_Daily!J7) | H7: =IF(C7="aFRR+",DAMAS_Daily!E7,DAMAS_Daily!F7) | I7: =IF(C7="aFRR+",DAMAS_Daily!G7,DAMAS_Daily!H7) | J7: =IF(C7="aFRR+",DAMAS_Daily!C7,DAMAS_Daily!D7) | K7: =IF(C7="aFRR+",MIN(DAMAS_Daily!C7*market_share_C*acceptance_rate*stack_activation,power_mw*hours_per_day,capacity_mwh),MIN(DAMAS_Daily!D7*market_share_C*acceptance_rate*stack_activation,power_mw*hours_per_day,capacity_mwh)) | L7: =IF(K7>=capacity_mwh-0.01,"yes","no") | M7: =IF(C7="aFRR+",(MIN(DAMAS_Daily!C7*market_share_C*acceptance_rate*stack_activation,power_mw*hours_per_day,capacity_mwh))*DAMAS_Daily!E7*activation_mult_C,(MIN(DAMAS_Daily!D7*market_share_C*acceptance_rate*stack_activation,power_mw*hours_per_day,capacity_mwh))*DAMAS_Daily!F7*activation_mult_C) | N7: =F7+M7
